[2024-10-31T19:00:01.562+0000] {local_task_job_runner.py:123} INFO - ::group::Pre task execution logs
[2024-10-31T19:00:01.585+0000] {taskinstance.py:2612} INFO - Dependencies all met for dep_context=non-requeueable deps ti=<TaskInstance: write_kafka.load_connections scheduled__2024-10-31T18:00:00+00:00 [queued]>
[2024-10-31T19:00:01.599+0000] {taskinstance.py:2612} INFO - Dependencies all met for dep_context=requeueable deps ti=<TaskInstance: write_kafka.load_connections scheduled__2024-10-31T18:00:00+00:00 [queued]>
[2024-10-31T19:00:01.600+0000] {taskinstance.py:2865} INFO - Starting attempt 1 of 2
[2024-10-31T19:00:01.623+0000] {taskinstance.py:2888} INFO - Executing <Task(PythonOperator): load_connections> on 2024-10-31 18:00:00+00:00
[2024-10-31T19:00:01.632+0000] {warnings.py:112} WARNING - /home/***/.local/lib/python3.12/site-packages/***/task/task_runner/standard_task_runner.py:70: DeprecationWarning: This process (pid=1341) is multi-threaded, use of fork() may lead to deadlocks in the child.
  pid = os.fork()

[2024-10-31T19:00:01.634+0000] {standard_task_runner.py:72} INFO - Started process 1343 to run task
[2024-10-31T19:00:01.634+0000] {standard_task_runner.py:104} INFO - Running: ['***', 'tasks', 'run', 'write_kafka', 'load_connections', 'scheduled__2024-10-31T18:00:00+00:00', '--job-id', '57', '--raw', '--subdir', 'DAGS_FOLDER/write_kafka.py', '--cfg-path', '/tmp/tmp6byhwewo']
[2024-10-31T19:00:01.638+0000] {standard_task_runner.py:105} INFO - Job 57: Subtask load_connections
[2024-10-31T19:00:01.700+0000] {task_command.py:467} INFO - Running <TaskInstance: write_kafka.load_connections scheduled__2024-10-31T18:00:00+00:00 [running]> on host 764f828e7588
[2024-10-31T19:00:02.131+0000] {taskinstance.py:3131} INFO - Exporting env vars: AIRFLOW_CTX_DAG_OWNER='***' AIRFLOW_CTX_DAG_ID='write_kafka' AIRFLOW_CTX_TASK_ID='load_connections' AIRFLOW_CTX_EXECUTION_DATE='2024-10-31T18:00:00+00:00' AIRFLOW_CTX_TRY_NUMBER='1' AIRFLOW_CTX_DAG_RUN_ID='scheduled__2024-10-31T18:00:00+00:00'
[2024-10-31T19:00:02.134+0000] {taskinstance.py:731} INFO - ::endgroup::
[2024-10-31T19:00:02.181+0000] {crypto.py:82} WARNING - empty cryptography key - values will not be stored encrypted.
[2024-10-31T19:00:02.191+0000] {python.py:240} INFO - Done. Returned value was: None
[2024-10-31T19:00:02.203+0000] {taskinstance.py:340} INFO - ::group::Post task execution logs
[2024-10-31T19:00:02.204+0000] {taskinstance.py:352} INFO - Marking task as SUCCESS. dag_id=write_kafka, task_id=load_connections, run_id=scheduled__2024-10-31T18:00:00+00:00, execution_date=20241031T180000, start_date=20241031T190001, end_date=20241031T190002
[2024-10-31T19:00:02.253+0000] {local_task_job_runner.py:266} INFO - Task exited with return code 0
[2024-10-31T19:00:02.316+0000] {taskinstance.py:3900} INFO - 1 downstream tasks scheduled from follow-on schedule check
[2024-10-31T19:00:02.326+0000] {local_task_job_runner.py:245} INFO - ::endgroup::
[2024-10-31T19:27:23.169+0000] {local_task_job_runner.py:123} INFO - ::group::Pre task execution logs
[2024-10-31T19:27:23.204+0000] {taskinstance.py:2612} INFO - Dependencies all met for dep_context=non-requeueable deps ti=<TaskInstance: write_kafka.load_connections scheduled__2024-10-31T18:00:00+00:00 [queued]>
[2024-10-31T19:27:23.219+0000] {taskinstance.py:2612} INFO - Dependencies all met for dep_context=requeueable deps ti=<TaskInstance: write_kafka.load_connections scheduled__2024-10-31T18:00:00+00:00 [queued]>
[2024-10-31T19:27:23.220+0000] {taskinstance.py:2865} INFO - Starting attempt 1 of 2
[2024-10-31T19:27:23.274+0000] {taskinstance.py:2888} INFO - Executing <Task(PythonOperator): load_connections> on 2024-10-31 18:00:00+00:00
[2024-10-31T19:27:23.287+0000] {warnings.py:112} WARNING - /home/***/.local/lib/python3.12/site-packages/***/task/task_runner/standard_task_runner.py:70: DeprecationWarning: This process (pid=72) is multi-threaded, use of fork() may lead to deadlocks in the child.
  pid = os.fork()

[2024-10-31T19:27:23.291+0000] {standard_task_runner.py:72} INFO - Started process 84 to run task
[2024-10-31T19:27:23.291+0000] {standard_task_runner.py:104} INFO - Running: ['***', 'tasks', 'run', 'write_kafka', 'load_connections', 'scheduled__2024-10-31T18:00:00+00:00', '--job-id', '3', '--raw', '--subdir', 'DAGS_FOLDER/write_kafka.py', '--cfg-path', '/tmp/tmpn_saierc']
[2024-10-31T19:27:23.295+0000] {standard_task_runner.py:105} INFO - Job 3: Subtask load_connections
[2024-10-31T19:27:23.705+0000] {task_command.py:467} INFO - Running <TaskInstance: write_kafka.load_connections scheduled__2024-10-31T18:00:00+00:00 [running]> on host d699ba927b11
[2024-10-31T19:27:23.837+0000] {taskinstance.py:3131} INFO - Exporting env vars: AIRFLOW_CTX_DAG_OWNER='***' AIRFLOW_CTX_DAG_ID='write_kafka' AIRFLOW_CTX_TASK_ID='load_connections' AIRFLOW_CTX_EXECUTION_DATE='2024-10-31T18:00:00+00:00' AIRFLOW_CTX_TRY_NUMBER='1' AIRFLOW_CTX_DAG_RUN_ID='scheduled__2024-10-31T18:00:00+00:00'
[2024-10-31T19:27:23.838+0000] {taskinstance.py:731} INFO - ::endgroup::
[2024-10-31T19:27:23.899+0000] {crypto.py:82} WARNING - empty cryptography key - values will not be stored encrypted.
[2024-10-31T19:27:23.947+0000] {taskinstance.py:3310} ERROR - Task failed with exception
Traceback (most recent call last):
  File "/home/airflow/.local/lib/python3.12/site-packages/sqlalchemy/engine/base.py", line 1910, in _execute_context
    self.dialect.do_execute(
  File "/home/airflow/.local/lib/python3.12/site-packages/sqlalchemy/engine/default.py", line 736, in do_execute
    cursor.execute(statement, parameters)
psycopg2.errors.UniqueViolation: duplicate key value violates unique constraint "connection_conn_id_uq"
DETAIL:  Key (conn_id)=(donki-cme-broker) already exists.


The above exception was the direct cause of the following exception:

Traceback (most recent call last):
  File "/home/airflow/.local/lib/python3.12/site-packages/airflow/models/taskinstance.py", line 767, in _execute_task
    result = _execute_callable(context=context, **execute_callable_kwargs)
             ^^^^^^^^^^^^^^^^^^^^^^^^^^^^^^^^^^^^^^^^^^^^^^^^^^^^^^^^^^^^^
  File "/home/airflow/.local/lib/python3.12/site-packages/airflow/models/taskinstance.py", line 733, in _execute_callable
    return ExecutionCallableRunner(
           ^^^^^^^^^^^^^^^^^^^^^^^^
  File "/home/airflow/.local/lib/python3.12/site-packages/airflow/utils/operator_helpers.py", line 252, in run
    return self.func(*args, **kwargs)
           ^^^^^^^^^^^^^^^^^^^^^^^^^^
  File "/home/airflow/.local/lib/python3.12/site-packages/airflow/models/baseoperator.py", line 406, in wrapper
    return func(self, *args, **kwargs)
           ^^^^^^^^^^^^^^^^^^^^^^^^^^^
  File "/home/airflow/.local/lib/python3.12/site-packages/airflow/operators/python.py", line 238, in execute
    return_value = self.execute_callable()
                   ^^^^^^^^^^^^^^^^^^^^^^^
  File "/home/airflow/.local/lib/python3.12/site-packages/airflow/operators/python.py", line 256, in execute_callable
    return runner.run(*self.op_args, **self.op_kwargs)
           ^^^^^^^^^^^^^^^^^^^^^^^^^^^^^^^^^^^^^^^^^^^
  File "/home/airflow/.local/lib/python3.12/site-packages/airflow/utils/operator_helpers.py", line 252, in run
    return self.func(*args, **kwargs)
           ^^^^^^^^^^^^^^^^^^^^^^^^^^
  File "/opt/airflow/dags/write_kafka.py", line 27, in load_connections
    db.merge_conn(
  File "/home/airflow/.local/lib/python3.12/site-packages/airflow/utils/session.py", line 97, in wrapper
    return func(*args, session=session, **kwargs)
           ^^^^^^^^^^^^^^^^^^^^^^^^^^^^^^^^^^^^^^
  File "/home/airflow/.local/lib/python3.12/site-packages/airflow/utils/db.py", line 134, in merge_conn
    session.commit()
  File "/home/airflow/.local/lib/python3.12/site-packages/sqlalchemy/orm/session.py", line 1454, in commit
    self._transaction.commit(_to_root=self.future)
  File "/home/airflow/.local/lib/python3.12/site-packages/sqlalchemy/orm/session.py", line 832, in commit
    self._prepare_impl()
  File "/home/airflow/.local/lib/python3.12/site-packages/sqlalchemy/orm/session.py", line 811, in _prepare_impl
    self.session.flush()
  File "/home/airflow/.local/lib/python3.12/site-packages/sqlalchemy/orm/session.py", line 3449, in flush
    self._flush(objects)
  File "/home/airflow/.local/lib/python3.12/site-packages/sqlalchemy/orm/session.py", line 3588, in _flush
    with util.safe_reraise():
         ^^^^^^^^^^^^^^^^^^^
  File "/home/airflow/.local/lib/python3.12/site-packages/sqlalchemy/util/langhelpers.py", line 70, in __exit__
    compat.raise_(
  File "/home/airflow/.local/lib/python3.12/site-packages/sqlalchemy/util/compat.py", line 211, in raise_
    raise exception
  File "/home/airflow/.local/lib/python3.12/site-packages/sqlalchemy/orm/session.py", line 3549, in _flush
    flush_context.execute()
  File "/home/airflow/.local/lib/python3.12/site-packages/sqlalchemy/orm/unitofwork.py", line 456, in execute
    rec.execute(self)
  File "/home/airflow/.local/lib/python3.12/site-packages/sqlalchemy/orm/unitofwork.py", line 630, in execute
    util.preloaded.orm_persistence.save_obj(
  File "/home/airflow/.local/lib/python3.12/site-packages/sqlalchemy/orm/persistence.py", line 245, in save_obj
    _emit_insert_statements(
  File "/home/airflow/.local/lib/python3.12/site-packages/sqlalchemy/orm/persistence.py", line 1238, in _emit_insert_statements
    result = connection._execute_20(
             ^^^^^^^^^^^^^^^^^^^^^^^
  File "/home/airflow/.local/lib/python3.12/site-packages/sqlalchemy/engine/base.py", line 1710, in _execute_20
    return meth(self, args_10style, kwargs_10style, execution_options)
           ^^^^^^^^^^^^^^^^^^^^^^^^^^^^^^^^^^^^^^^^^^^^^^^^^^^^^^^^^^^
  File "/home/airflow/.local/lib/python3.12/site-packages/sqlalchemy/sql/elements.py", line 334, in _execute_on_connection
    return connection._execute_clauseelement(
           ^^^^^^^^^^^^^^^^^^^^^^^^^^^^^^^^^^
  File "/home/airflow/.local/lib/python3.12/site-packages/sqlalchemy/engine/base.py", line 1577, in _execute_clauseelement
    ret = self._execute_context(
          ^^^^^^^^^^^^^^^^^^^^^^
  File "/home/airflow/.local/lib/python3.12/site-packages/sqlalchemy/engine/base.py", line 1953, in _execute_context
    self._handle_dbapi_exception(
  File "/home/airflow/.local/lib/python3.12/site-packages/sqlalchemy/engine/base.py", line 2134, in _handle_dbapi_exception
    util.raise_(
  File "/home/airflow/.local/lib/python3.12/site-packages/sqlalchemy/util/compat.py", line 211, in raise_
    raise exception
  File "/home/airflow/.local/lib/python3.12/site-packages/sqlalchemy/engine/base.py", line 1910, in _execute_context
    self.dialect.do_execute(
  File "/home/airflow/.local/lib/python3.12/site-packages/sqlalchemy/engine/default.py", line 736, in do_execute
    cursor.execute(statement, parameters)
sqlalchemy.exc.IntegrityError: (psycopg2.errors.UniqueViolation) duplicate key value violates unique constraint "connection_conn_id_uq"
DETAIL:  Key (conn_id)=(donki-cme-broker) already exists.

[SQL: INSERT INTO connection (conn_id, conn_type, description, host, schema, login, password, port, is_encrypted, is_extra_encrypted, extra) VALUES (%(conn_id)s, %(conn_type)s, %(description)s, %(host)s, %(schema)s, %(login)s, %(password)s, %(port)s, %(is_encrypted)s, %(is_extra_encrypted)s, %(extra)s) RETURNING connection.id]
[parameters: {'conn_id': 'donki-cme-broker', 'conn_type': 'kafka', 'description': None, 'host': None, 'schema': None, 'login': None, 'password': None, 'port': None, 'is_encrypted': False, 'is_extra_encrypted': False, 'extra': '{"bootstrap.servers": "//localhost:29092"}'}]
(Background on this error at: https://sqlalche.me/e/14/gkpj)
[2024-10-31T19:27:23.995+0000] {taskinstance.py:1225} INFO - Marking task as UP_FOR_RETRY. dag_id=write_kafka, task_id=load_connections, run_id=scheduled__2024-10-31T18:00:00+00:00, execution_date=20241031T180000, start_date=20241031T192723, end_date=20241031T192723
[2024-10-31T19:27:24.023+0000] {taskinstance.py:340} INFO - ::group::Post task execution logs
[2024-10-31T19:27:24.024+0000] {standard_task_runner.py:124} ERROR - Failed to execute job 3 for task load_connections ((psycopg2.errors.UniqueViolation) duplicate key value violates unique constraint "connection_conn_id_uq"
DETAIL:  Key (conn_id)=(donki-cme-broker) already exists.

[SQL: INSERT INTO connection (conn_id, conn_type, description, host, schema, login, password, port, is_encrypted, is_extra_encrypted, extra) VALUES (%(conn_id)s, %(conn_type)s, %(description)s, %(host)s, %(schema)s, %(login)s, %(password)s, %(port)s, %(is_encrypted)s, %(is_extra_encrypted)s, %(extra)s) RETURNING connection.id]
[parameters: {'conn_id': 'donki-cme-broker', 'conn_type': 'kafka', 'description': None, 'host': None, 'schema': None, 'login': None, 'password': None, 'port': None, 'is_encrypted': False, 'is_extra_encrypted': False, 'extra': '{"bootstrap.servers": "//localhost:29092"}'}]
(Background on this error at: https://sqlalche.me/e/14/gkpj); 84)
Traceback (most recent call last):
  File "/home/airflow/.local/lib/python3.12/site-packages/sqlalchemy/engine/base.py", line 1910, in _execute_context
    self.dialect.do_execute(
  File "/home/airflow/.local/lib/python3.12/site-packages/sqlalchemy/engine/default.py", line 736, in do_execute
    cursor.execute(statement, parameters)
psycopg2.errors.UniqueViolation: duplicate key value violates unique constraint "connection_conn_id_uq"
DETAIL:  Key (conn_id)=(donki-cme-broker) already exists.


The above exception was the direct cause of the following exception:

Traceback (most recent call last):
  File "/home/airflow/.local/lib/python3.12/site-packages/airflow/task/task_runner/standard_task_runner.py", line 117, in _start_by_fork
    ret = args.func(args, dag=self.dag)
          ^^^^^^^^^^^^^^^^^^^^^^^^^^^^^
  File "/home/airflow/.local/lib/python3.12/site-packages/airflow/cli/cli_config.py", line 49, in command
    return func(*args, **kwargs)
           ^^^^^^^^^^^^^^^^^^^^^
  File "/home/airflow/.local/lib/python3.12/site-packages/airflow/utils/cli.py", line 115, in wrapper
    return f(*args, **kwargs)
           ^^^^^^^^^^^^^^^^^^
  File "/home/airflow/.local/lib/python3.12/site-packages/airflow/cli/commands/task_command.py", line 483, in task_run
    task_return_code = _run_task_by_selected_method(args, _dag, ti)
                       ^^^^^^^^^^^^^^^^^^^^^^^^^^^^^^^^^^^^^^^^^^^^
  File "/home/airflow/.local/lib/python3.12/site-packages/airflow/cli/commands/task_command.py", line 256, in _run_task_by_selected_method
    return _run_raw_task(args, ti)
           ^^^^^^^^^^^^^^^^^^^^^^^
  File "/home/airflow/.local/lib/python3.12/site-packages/airflow/cli/commands/task_command.py", line 341, in _run_raw_task
    return ti._run_raw_task(
           ^^^^^^^^^^^^^^^^^
  File "/home/airflow/.local/lib/python3.12/site-packages/airflow/utils/session.py", line 97, in wrapper
    return func(*args, session=session, **kwargs)
           ^^^^^^^^^^^^^^^^^^^^^^^^^^^^^^^^^^^^^^
  File "/home/airflow/.local/lib/python3.12/site-packages/airflow/models/taskinstance.py", line 3004, in _run_raw_task
    return _run_raw_task(
           ^^^^^^^^^^^^^^
  File "/home/airflow/.local/lib/python3.12/site-packages/airflow/models/taskinstance.py", line 273, in _run_raw_task
    TaskInstance._execute_task_with_callbacks(
  File "/home/airflow/.local/lib/python3.12/site-packages/airflow/models/taskinstance.py", line 3158, in _execute_task_with_callbacks
    result = self._execute_task(context, task_orig)
             ^^^^^^^^^^^^^^^^^^^^^^^^^^^^^^^^^^^^^^
  File "/home/airflow/.local/lib/python3.12/site-packages/airflow/models/taskinstance.py", line 3182, in _execute_task
    return _execute_task(self, context, task_orig)
           ^^^^^^^^^^^^^^^^^^^^^^^^^^^^^^^^^^^^^^^
  File "/home/airflow/.local/lib/python3.12/site-packages/airflow/models/taskinstance.py", line 767, in _execute_task
    result = _execute_callable(context=context, **execute_callable_kwargs)
             ^^^^^^^^^^^^^^^^^^^^^^^^^^^^^^^^^^^^^^^^^^^^^^^^^^^^^^^^^^^^^
  File "/home/airflow/.local/lib/python3.12/site-packages/airflow/models/taskinstance.py", line 733, in _execute_callable
    return ExecutionCallableRunner(
           ^^^^^^^^^^^^^^^^^^^^^^^^
  File "/home/airflow/.local/lib/python3.12/site-packages/airflow/utils/operator_helpers.py", line 252, in run
    return self.func(*args, **kwargs)
           ^^^^^^^^^^^^^^^^^^^^^^^^^^
  File "/home/airflow/.local/lib/python3.12/site-packages/airflow/models/baseoperator.py", line 406, in wrapper
    return func(self, *args, **kwargs)
           ^^^^^^^^^^^^^^^^^^^^^^^^^^^
  File "/home/airflow/.local/lib/python3.12/site-packages/airflow/operators/python.py", line 238, in execute
    return_value = self.execute_callable()
                   ^^^^^^^^^^^^^^^^^^^^^^^
  File "/home/airflow/.local/lib/python3.12/site-packages/airflow/operators/python.py", line 256, in execute_callable
    return runner.run(*self.op_args, **self.op_kwargs)
           ^^^^^^^^^^^^^^^^^^^^^^^^^^^^^^^^^^^^^^^^^^^
  File "/home/airflow/.local/lib/python3.12/site-packages/airflow/utils/operator_helpers.py", line 252, in run
    return self.func(*args, **kwargs)
           ^^^^^^^^^^^^^^^^^^^^^^^^^^
  File "/opt/airflow/dags/write_kafka.py", line 27, in load_connections
    db.merge_conn(
  File "/home/airflow/.local/lib/python3.12/site-packages/airflow/utils/session.py", line 97, in wrapper
    return func(*args, session=session, **kwargs)
           ^^^^^^^^^^^^^^^^^^^^^^^^^^^^^^^^^^^^^^
  File "/home/airflow/.local/lib/python3.12/site-packages/airflow/utils/db.py", line 134, in merge_conn
    session.commit()
  File "/home/airflow/.local/lib/python3.12/site-packages/sqlalchemy/orm/session.py", line 1454, in commit
    self._transaction.commit(_to_root=self.future)
  File "/home/airflow/.local/lib/python3.12/site-packages/sqlalchemy/orm/session.py", line 832, in commit
    self._prepare_impl()
  File "/home/airflow/.local/lib/python3.12/site-packages/sqlalchemy/orm/session.py", line 811, in _prepare_impl
    self.session.flush()
  File "/home/airflow/.local/lib/python3.12/site-packages/sqlalchemy/orm/session.py", line 3449, in flush
    self._flush(objects)
  File "/home/airflow/.local/lib/python3.12/site-packages/sqlalchemy/orm/session.py", line 3588, in _flush
    with util.safe_reraise():
         ^^^^^^^^^^^^^^^^^^^
  File "/home/airflow/.local/lib/python3.12/site-packages/sqlalchemy/util/langhelpers.py", line 70, in __exit__
    compat.raise_(
  File "/home/airflow/.local/lib/python3.12/site-packages/sqlalchemy/util/compat.py", line 211, in raise_
    raise exception
  File "/home/airflow/.local/lib/python3.12/site-packages/sqlalchemy/orm/session.py", line 3549, in _flush
    flush_context.execute()
  File "/home/airflow/.local/lib/python3.12/site-packages/sqlalchemy/orm/unitofwork.py", line 456, in execute
    rec.execute(self)
  File "/home/airflow/.local/lib/python3.12/site-packages/sqlalchemy/orm/unitofwork.py", line 630, in execute
    util.preloaded.orm_persistence.save_obj(
  File "/home/airflow/.local/lib/python3.12/site-packages/sqlalchemy/orm/persistence.py", line 245, in save_obj
    _emit_insert_statements(
  File "/home/airflow/.local/lib/python3.12/site-packages/sqlalchemy/orm/persistence.py", line 1238, in _emit_insert_statements
    result = connection._execute_20(
             ^^^^^^^^^^^^^^^^^^^^^^^
  File "/home/airflow/.local/lib/python3.12/site-packages/sqlalchemy/engine/base.py", line 1710, in _execute_20
    return meth(self, args_10style, kwargs_10style, execution_options)
           ^^^^^^^^^^^^^^^^^^^^^^^^^^^^^^^^^^^^^^^^^^^^^^^^^^^^^^^^^^^
  File "/home/airflow/.local/lib/python3.12/site-packages/sqlalchemy/sql/elements.py", line 334, in _execute_on_connection
    return connection._execute_clauseelement(
           ^^^^^^^^^^^^^^^^^^^^^^^^^^^^^^^^^^
  File "/home/airflow/.local/lib/python3.12/site-packages/sqlalchemy/engine/base.py", line 1577, in _execute_clauseelement
    ret = self._execute_context(
          ^^^^^^^^^^^^^^^^^^^^^^
  File "/home/airflow/.local/lib/python3.12/site-packages/sqlalchemy/engine/base.py", line 1953, in _execute_context
    self._handle_dbapi_exception(
  File "/home/airflow/.local/lib/python3.12/site-packages/sqlalchemy/engine/base.py", line 2134, in _handle_dbapi_exception
    util.raise_(
  File "/home/airflow/.local/lib/python3.12/site-packages/sqlalchemy/util/compat.py", line 211, in raise_
    raise exception
  File "/home/airflow/.local/lib/python3.12/site-packages/sqlalchemy/engine/base.py", line 1910, in _execute_context
    self.dialect.do_execute(
  File "/home/airflow/.local/lib/python3.12/site-packages/sqlalchemy/engine/default.py", line 736, in do_execute
    cursor.execute(statement, parameters)
sqlalchemy.exc.IntegrityError: (psycopg2.errors.UniqueViolation) duplicate key value violates unique constraint "connection_conn_id_uq"
DETAIL:  Key (conn_id)=(donki-cme-broker) already exists.

[SQL: INSERT INTO connection (conn_id, conn_type, description, host, schema, login, password, port, is_encrypted, is_extra_encrypted, extra) VALUES (%(conn_id)s, %(conn_type)s, %(description)s, %(host)s, %(schema)s, %(login)s, %(password)s, %(port)s, %(is_encrypted)s, %(is_extra_encrypted)s, %(extra)s) RETURNING connection.id]
[parameters: {'conn_id': 'donki-cme-broker', 'conn_type': 'kafka', 'description': None, 'host': None, 'schema': None, 'login': None, 'password': None, 'port': None, 'is_encrypted': False, 'is_extra_encrypted': False, 'extra': '{"bootstrap.servers": "//localhost:29092"}'}]
(Background on this error at: https://sqlalche.me/e/14/gkpj)
[2024-10-31T19:27:24.072+0000] {local_task_job_runner.py:266} INFO - Task exited with return code 1
[2024-10-31T19:27:24.357+0000] {taskinstance.py:3900} INFO - 0 downstream tasks scheduled from follow-on schedule check
[2024-10-31T19:27:24.366+0000] {local_task_job_runner.py:245} INFO - ::endgroup::
[2024-10-31T19:44:05.698+0000] {local_task_job_runner.py:123} INFO - ::group::Pre task execution logs
[2024-10-31T19:44:05.721+0000] {taskinstance.py:2612} INFO - Dependencies all met for dep_context=non-requeueable deps ti=<TaskInstance: write_kafka.load_connections scheduled__2024-10-31T18:00:00+00:00 [queued]>
[2024-10-31T19:44:05.734+0000] {taskinstance.py:2612} INFO - Dependencies all met for dep_context=requeueable deps ti=<TaskInstance: write_kafka.load_connections scheduled__2024-10-31T18:00:00+00:00 [queued]>
[2024-10-31T19:44:05.735+0000] {taskinstance.py:2865} INFO - Starting attempt 1 of 2
[2024-10-31T19:44:05.763+0000] {taskinstance.py:2888} INFO - Executing <Task(PythonOperator): load_connections> on 2024-10-31 18:00:00+00:00
[2024-10-31T19:44:05.773+0000] {warnings.py:112} WARNING - /home/***/.local/lib/python3.12/site-packages/***/task/task_runner/standard_task_runner.py:70: DeprecationWarning: This process (pid=72) is multi-threaded, use of fork() may lead to deadlocks in the child.
  pid = os.fork()

[2024-10-31T19:44:05.777+0000] {standard_task_runner.py:72} INFO - Started process 76 to run task
[2024-10-31T19:44:05.777+0000] {standard_task_runner.py:104} INFO - Running: ['***', 'tasks', 'run', 'write_kafka', 'load_connections', 'scheduled__2024-10-31T18:00:00+00:00', '--job-id', '4', '--raw', '--subdir', 'DAGS_FOLDER/write_kafka.py', '--cfg-path', '/tmp/tmp9hitsv0v']
[2024-10-31T19:44:05.781+0000] {standard_task_runner.py:105} INFO - Job 4: Subtask load_connections
[2024-10-31T19:44:06.173+0000] {task_command.py:467} INFO - Running <TaskInstance: write_kafka.load_connections scheduled__2024-10-31T18:00:00+00:00 [running]> on host 16db0ed5f1c9
[2024-10-31T19:44:06.282+0000] {taskinstance.py:3131} INFO - Exporting env vars: AIRFLOW_CTX_DAG_OWNER='***' AIRFLOW_CTX_DAG_ID='write_kafka' AIRFLOW_CTX_TASK_ID='load_connections' AIRFLOW_CTX_EXECUTION_DATE='2024-10-31T18:00:00+00:00' AIRFLOW_CTX_TRY_NUMBER='1' AIRFLOW_CTX_DAG_RUN_ID='scheduled__2024-10-31T18:00:00+00:00'
[2024-10-31T19:44:06.284+0000] {taskinstance.py:731} INFO - ::endgroup::
[2024-10-31T19:44:06.334+0000] {crypto.py:82} WARNING - empty cryptography key - values will not be stored encrypted.
[2024-10-31T19:44:06.350+0000] {taskinstance.py:3310} ERROR - Task failed with exception
Traceback (most recent call last):
  File "/home/airflow/.local/lib/python3.12/site-packages/sqlalchemy/engine/base.py", line 1910, in _execute_context
    self.dialect.do_execute(
  File "/home/airflow/.local/lib/python3.12/site-packages/sqlalchemy/engine/default.py", line 736, in do_execute
    cursor.execute(statement, parameters)
psycopg2.errors.UniqueViolation: duplicate key value violates unique constraint "connection_conn_id_uq"
DETAIL:  Key (conn_id)=(donki-cme-broker) already exists.


The above exception was the direct cause of the following exception:

Traceback (most recent call last):
  File "/home/airflow/.local/lib/python3.12/site-packages/airflow/models/taskinstance.py", line 767, in _execute_task
    result = _execute_callable(context=context, **execute_callable_kwargs)
             ^^^^^^^^^^^^^^^^^^^^^^^^^^^^^^^^^^^^^^^^^^^^^^^^^^^^^^^^^^^^^
  File "/home/airflow/.local/lib/python3.12/site-packages/airflow/models/taskinstance.py", line 733, in _execute_callable
    return ExecutionCallableRunner(
           ^^^^^^^^^^^^^^^^^^^^^^^^
  File "/home/airflow/.local/lib/python3.12/site-packages/airflow/utils/operator_helpers.py", line 252, in run
    return self.func(*args, **kwargs)
           ^^^^^^^^^^^^^^^^^^^^^^^^^^
  File "/home/airflow/.local/lib/python3.12/site-packages/airflow/models/baseoperator.py", line 406, in wrapper
    return func(self, *args, **kwargs)
           ^^^^^^^^^^^^^^^^^^^^^^^^^^^
  File "/home/airflow/.local/lib/python3.12/site-packages/airflow/operators/python.py", line 238, in execute
    return_value = self.execute_callable()
                   ^^^^^^^^^^^^^^^^^^^^^^^
  File "/home/airflow/.local/lib/python3.12/site-packages/airflow/operators/python.py", line 256, in execute_callable
    return runner.run(*self.op_args, **self.op_kwargs)
           ^^^^^^^^^^^^^^^^^^^^^^^^^^^^^^^^^^^^^^^^^^^
  File "/home/airflow/.local/lib/python3.12/site-packages/airflow/utils/operator_helpers.py", line 252, in run
    return self.func(*args, **kwargs)
           ^^^^^^^^^^^^^^^^^^^^^^^^^^
  File "/opt/airflow/dags/write_kafka.py", line 27, in load_connections
    db.merge_conn(
  File "/home/airflow/.local/lib/python3.12/site-packages/airflow/utils/session.py", line 97, in wrapper
    return func(*args, session=session, **kwargs)
           ^^^^^^^^^^^^^^^^^^^^^^^^^^^^^^^^^^^^^^
  File "/home/airflow/.local/lib/python3.12/site-packages/airflow/utils/db.py", line 134, in merge_conn
    session.commit()
  File "/home/airflow/.local/lib/python3.12/site-packages/sqlalchemy/orm/session.py", line 1454, in commit
    self._transaction.commit(_to_root=self.future)
  File "/home/airflow/.local/lib/python3.12/site-packages/sqlalchemy/orm/session.py", line 832, in commit
    self._prepare_impl()
  File "/home/airflow/.local/lib/python3.12/site-packages/sqlalchemy/orm/session.py", line 811, in _prepare_impl
    self.session.flush()
  File "/home/airflow/.local/lib/python3.12/site-packages/sqlalchemy/orm/session.py", line 3449, in flush
    self._flush(objects)
  File "/home/airflow/.local/lib/python3.12/site-packages/sqlalchemy/orm/session.py", line 3588, in _flush
    with util.safe_reraise():
         ^^^^^^^^^^^^^^^^^^^
  File "/home/airflow/.local/lib/python3.12/site-packages/sqlalchemy/util/langhelpers.py", line 70, in __exit__
    compat.raise_(
  File "/home/airflow/.local/lib/python3.12/site-packages/sqlalchemy/util/compat.py", line 211, in raise_
    raise exception
  File "/home/airflow/.local/lib/python3.12/site-packages/sqlalchemy/orm/session.py", line 3549, in _flush
    flush_context.execute()
  File "/home/airflow/.local/lib/python3.12/site-packages/sqlalchemy/orm/unitofwork.py", line 456, in execute
    rec.execute(self)
  File "/home/airflow/.local/lib/python3.12/site-packages/sqlalchemy/orm/unitofwork.py", line 630, in execute
    util.preloaded.orm_persistence.save_obj(
  File "/home/airflow/.local/lib/python3.12/site-packages/sqlalchemy/orm/persistence.py", line 245, in save_obj
    _emit_insert_statements(
  File "/home/airflow/.local/lib/python3.12/site-packages/sqlalchemy/orm/persistence.py", line 1238, in _emit_insert_statements
    result = connection._execute_20(
             ^^^^^^^^^^^^^^^^^^^^^^^
  File "/home/airflow/.local/lib/python3.12/site-packages/sqlalchemy/engine/base.py", line 1710, in _execute_20
    return meth(self, args_10style, kwargs_10style, execution_options)
           ^^^^^^^^^^^^^^^^^^^^^^^^^^^^^^^^^^^^^^^^^^^^^^^^^^^^^^^^^^^
  File "/home/airflow/.local/lib/python3.12/site-packages/sqlalchemy/sql/elements.py", line 334, in _execute_on_connection
    return connection._execute_clauseelement(
           ^^^^^^^^^^^^^^^^^^^^^^^^^^^^^^^^^^
  File "/home/airflow/.local/lib/python3.12/site-packages/sqlalchemy/engine/base.py", line 1577, in _execute_clauseelement
    ret = self._execute_context(
          ^^^^^^^^^^^^^^^^^^^^^^
  File "/home/airflow/.local/lib/python3.12/site-packages/sqlalchemy/engine/base.py", line 1953, in _execute_context
    self._handle_dbapi_exception(
  File "/home/airflow/.local/lib/python3.12/site-packages/sqlalchemy/engine/base.py", line 2134, in _handle_dbapi_exception
    util.raise_(
  File "/home/airflow/.local/lib/python3.12/site-packages/sqlalchemy/util/compat.py", line 211, in raise_
    raise exception
  File "/home/airflow/.local/lib/python3.12/site-packages/sqlalchemy/engine/base.py", line 1910, in _execute_context
    self.dialect.do_execute(
  File "/home/airflow/.local/lib/python3.12/site-packages/sqlalchemy/engine/default.py", line 736, in do_execute
    cursor.execute(statement, parameters)
sqlalchemy.exc.IntegrityError: (psycopg2.errors.UniqueViolation) duplicate key value violates unique constraint "connection_conn_id_uq"
DETAIL:  Key (conn_id)=(donki-cme-broker) already exists.

[SQL: INSERT INTO connection (conn_id, conn_type, description, host, schema, login, password, port, is_encrypted, is_extra_encrypted, extra) VALUES (%(conn_id)s, %(conn_type)s, %(description)s, %(host)s, %(schema)s, %(login)s, %(password)s, %(port)s, %(is_encrypted)s, %(is_extra_encrypted)s, %(extra)s) RETURNING connection.id]
[parameters: {'conn_id': 'donki-cme-broker', 'conn_type': 'kafka', 'description': None, 'host': None, 'schema': None, 'login': None, 'password': None, 'port': None, 'is_encrypted': False, 'is_extra_encrypted': False, 'extra': '{"bootstrap.servers": "broker-1:19092"}'}]
(Background on this error at: https://sqlalche.me/e/14/gkpj)
[2024-10-31T19:44:06.381+0000] {taskinstance.py:1225} INFO - Marking task as UP_FOR_RETRY. dag_id=write_kafka, task_id=load_connections, run_id=scheduled__2024-10-31T18:00:00+00:00, execution_date=20241031T180000, start_date=20241031T194405, end_date=20241031T194406
[2024-10-31T19:44:06.411+0000] {taskinstance.py:340} INFO - ::group::Post task execution logs
[2024-10-31T19:44:06.412+0000] {standard_task_runner.py:124} ERROR - Failed to execute job 4 for task load_connections ((psycopg2.errors.UniqueViolation) duplicate key value violates unique constraint "connection_conn_id_uq"
DETAIL:  Key (conn_id)=(donki-cme-broker) already exists.

[SQL: INSERT INTO connection (conn_id, conn_type, description, host, schema, login, password, port, is_encrypted, is_extra_encrypted, extra) VALUES (%(conn_id)s, %(conn_type)s, %(description)s, %(host)s, %(schema)s, %(login)s, %(password)s, %(port)s, %(is_encrypted)s, %(is_extra_encrypted)s, %(extra)s) RETURNING connection.id]
[parameters: {'conn_id': 'donki-cme-broker', 'conn_type': 'kafka', 'description': None, 'host': None, 'schema': None, 'login': None, 'password': None, 'port': None, 'is_encrypted': False, 'is_extra_encrypted': False, 'extra': '{"bootstrap.servers": "broker-1:19092"}'}]
(Background on this error at: https://sqlalche.me/e/14/gkpj); 76)
Traceback (most recent call last):
  File "/home/airflow/.local/lib/python3.12/site-packages/sqlalchemy/engine/base.py", line 1910, in _execute_context
    self.dialect.do_execute(
  File "/home/airflow/.local/lib/python3.12/site-packages/sqlalchemy/engine/default.py", line 736, in do_execute
    cursor.execute(statement, parameters)
psycopg2.errors.UniqueViolation: duplicate key value violates unique constraint "connection_conn_id_uq"
DETAIL:  Key (conn_id)=(donki-cme-broker) already exists.


The above exception was the direct cause of the following exception:

Traceback (most recent call last):
  File "/home/airflow/.local/lib/python3.12/site-packages/airflow/task/task_runner/standard_task_runner.py", line 117, in _start_by_fork
    ret = args.func(args, dag=self.dag)
          ^^^^^^^^^^^^^^^^^^^^^^^^^^^^^
  File "/home/airflow/.local/lib/python3.12/site-packages/airflow/cli/cli_config.py", line 49, in command
    return func(*args, **kwargs)
           ^^^^^^^^^^^^^^^^^^^^^
  File "/home/airflow/.local/lib/python3.12/site-packages/airflow/utils/cli.py", line 115, in wrapper
    return f(*args, **kwargs)
           ^^^^^^^^^^^^^^^^^^
  File "/home/airflow/.local/lib/python3.12/site-packages/airflow/cli/commands/task_command.py", line 483, in task_run
    task_return_code = _run_task_by_selected_method(args, _dag, ti)
                       ^^^^^^^^^^^^^^^^^^^^^^^^^^^^^^^^^^^^^^^^^^^^
  File "/home/airflow/.local/lib/python3.12/site-packages/airflow/cli/commands/task_command.py", line 256, in _run_task_by_selected_method
    return _run_raw_task(args, ti)
           ^^^^^^^^^^^^^^^^^^^^^^^
  File "/home/airflow/.local/lib/python3.12/site-packages/airflow/cli/commands/task_command.py", line 341, in _run_raw_task
    return ti._run_raw_task(
           ^^^^^^^^^^^^^^^^^
  File "/home/airflow/.local/lib/python3.12/site-packages/airflow/utils/session.py", line 97, in wrapper
    return func(*args, session=session, **kwargs)
           ^^^^^^^^^^^^^^^^^^^^^^^^^^^^^^^^^^^^^^
  File "/home/airflow/.local/lib/python3.12/site-packages/airflow/models/taskinstance.py", line 3004, in _run_raw_task
    return _run_raw_task(
           ^^^^^^^^^^^^^^
  File "/home/airflow/.local/lib/python3.12/site-packages/airflow/models/taskinstance.py", line 273, in _run_raw_task
    TaskInstance._execute_task_with_callbacks(
  File "/home/airflow/.local/lib/python3.12/site-packages/airflow/models/taskinstance.py", line 3158, in _execute_task_with_callbacks
    result = self._execute_task(context, task_orig)
             ^^^^^^^^^^^^^^^^^^^^^^^^^^^^^^^^^^^^^^
  File "/home/airflow/.local/lib/python3.12/site-packages/airflow/models/taskinstance.py", line 3182, in _execute_task
    return _execute_task(self, context, task_orig)
           ^^^^^^^^^^^^^^^^^^^^^^^^^^^^^^^^^^^^^^^
  File "/home/airflow/.local/lib/python3.12/site-packages/airflow/models/taskinstance.py", line 767, in _execute_task
    result = _execute_callable(context=context, **execute_callable_kwargs)
             ^^^^^^^^^^^^^^^^^^^^^^^^^^^^^^^^^^^^^^^^^^^^^^^^^^^^^^^^^^^^^
  File "/home/airflow/.local/lib/python3.12/site-packages/airflow/models/taskinstance.py", line 733, in _execute_callable
    return ExecutionCallableRunner(
           ^^^^^^^^^^^^^^^^^^^^^^^^
  File "/home/airflow/.local/lib/python3.12/site-packages/airflow/utils/operator_helpers.py", line 252, in run
    return self.func(*args, **kwargs)
           ^^^^^^^^^^^^^^^^^^^^^^^^^^
  File "/home/airflow/.local/lib/python3.12/site-packages/airflow/models/baseoperator.py", line 406, in wrapper
    return func(self, *args, **kwargs)
           ^^^^^^^^^^^^^^^^^^^^^^^^^^^
  File "/home/airflow/.local/lib/python3.12/site-packages/airflow/operators/python.py", line 238, in execute
    return_value = self.execute_callable()
                   ^^^^^^^^^^^^^^^^^^^^^^^
  File "/home/airflow/.local/lib/python3.12/site-packages/airflow/operators/python.py", line 256, in execute_callable
    return runner.run(*self.op_args, **self.op_kwargs)
           ^^^^^^^^^^^^^^^^^^^^^^^^^^^^^^^^^^^^^^^^^^^
  File "/home/airflow/.local/lib/python3.12/site-packages/airflow/utils/operator_helpers.py", line 252, in run
    return self.func(*args, **kwargs)
           ^^^^^^^^^^^^^^^^^^^^^^^^^^
  File "/opt/airflow/dags/write_kafka.py", line 27, in load_connections
    db.merge_conn(
  File "/home/airflow/.local/lib/python3.12/site-packages/airflow/utils/session.py", line 97, in wrapper
    return func(*args, session=session, **kwargs)
           ^^^^^^^^^^^^^^^^^^^^^^^^^^^^^^^^^^^^^^
  File "/home/airflow/.local/lib/python3.12/site-packages/airflow/utils/db.py", line 134, in merge_conn
    session.commit()
  File "/home/airflow/.local/lib/python3.12/site-packages/sqlalchemy/orm/session.py", line 1454, in commit
    self._transaction.commit(_to_root=self.future)
  File "/home/airflow/.local/lib/python3.12/site-packages/sqlalchemy/orm/session.py", line 832, in commit
    self._prepare_impl()
  File "/home/airflow/.local/lib/python3.12/site-packages/sqlalchemy/orm/session.py", line 811, in _prepare_impl
    self.session.flush()
  File "/home/airflow/.local/lib/python3.12/site-packages/sqlalchemy/orm/session.py", line 3449, in flush
    self._flush(objects)
  File "/home/airflow/.local/lib/python3.12/site-packages/sqlalchemy/orm/session.py", line 3588, in _flush
    with util.safe_reraise():
         ^^^^^^^^^^^^^^^^^^^
  File "/home/airflow/.local/lib/python3.12/site-packages/sqlalchemy/util/langhelpers.py", line 70, in __exit__
    compat.raise_(
  File "/home/airflow/.local/lib/python3.12/site-packages/sqlalchemy/util/compat.py", line 211, in raise_
    raise exception
  File "/home/airflow/.local/lib/python3.12/site-packages/sqlalchemy/orm/session.py", line 3549, in _flush
    flush_context.execute()
  File "/home/airflow/.local/lib/python3.12/site-packages/sqlalchemy/orm/unitofwork.py", line 456, in execute
    rec.execute(self)
  File "/home/airflow/.local/lib/python3.12/site-packages/sqlalchemy/orm/unitofwork.py", line 630, in execute
    util.preloaded.orm_persistence.save_obj(
  File "/home/airflow/.local/lib/python3.12/site-packages/sqlalchemy/orm/persistence.py", line 245, in save_obj
    _emit_insert_statements(
  File "/home/airflow/.local/lib/python3.12/site-packages/sqlalchemy/orm/persistence.py", line 1238, in _emit_insert_statements
    result = connection._execute_20(
             ^^^^^^^^^^^^^^^^^^^^^^^
  File "/home/airflow/.local/lib/python3.12/site-packages/sqlalchemy/engine/base.py", line 1710, in _execute_20
    return meth(self, args_10style, kwargs_10style, execution_options)
           ^^^^^^^^^^^^^^^^^^^^^^^^^^^^^^^^^^^^^^^^^^^^^^^^^^^^^^^^^^^
  File "/home/airflow/.local/lib/python3.12/site-packages/sqlalchemy/sql/elements.py", line 334, in _execute_on_connection
    return connection._execute_clauseelement(
           ^^^^^^^^^^^^^^^^^^^^^^^^^^^^^^^^^^
  File "/home/airflow/.local/lib/python3.12/site-packages/sqlalchemy/engine/base.py", line 1577, in _execute_clauseelement
    ret = self._execute_context(
          ^^^^^^^^^^^^^^^^^^^^^^
  File "/home/airflow/.local/lib/python3.12/site-packages/sqlalchemy/engine/base.py", line 1953, in _execute_context
    self._handle_dbapi_exception(
  File "/home/airflow/.local/lib/python3.12/site-packages/sqlalchemy/engine/base.py", line 2134, in _handle_dbapi_exception
    util.raise_(
  File "/home/airflow/.local/lib/python3.12/site-packages/sqlalchemy/util/compat.py", line 211, in raise_
    raise exception
  File "/home/airflow/.local/lib/python3.12/site-packages/sqlalchemy/engine/base.py", line 1910, in _execute_context
    self.dialect.do_execute(
  File "/home/airflow/.local/lib/python3.12/site-packages/sqlalchemy/engine/default.py", line 736, in do_execute
    cursor.execute(statement, parameters)
sqlalchemy.exc.IntegrityError: (psycopg2.errors.UniqueViolation) duplicate key value violates unique constraint "connection_conn_id_uq"
DETAIL:  Key (conn_id)=(donki-cme-broker) already exists.

[SQL: INSERT INTO connection (conn_id, conn_type, description, host, schema, login, password, port, is_encrypted, is_extra_encrypted, extra) VALUES (%(conn_id)s, %(conn_type)s, %(description)s, %(host)s, %(schema)s, %(login)s, %(password)s, %(port)s, %(is_encrypted)s, %(is_extra_encrypted)s, %(extra)s) RETURNING connection.id]
[parameters: {'conn_id': 'donki-cme-broker', 'conn_type': 'kafka', 'description': None, 'host': None, 'schema': None, 'login': None, 'password': None, 'port': None, 'is_encrypted': False, 'is_extra_encrypted': False, 'extra': '{"bootstrap.servers": "broker-1:19092"}'}]
(Background on this error at: https://sqlalche.me/e/14/gkpj)
[2024-10-31T19:44:06.436+0000] {local_task_job_runner.py:266} INFO - Task exited with return code 1
[2024-10-31T19:44:06.732+0000] {taskinstance.py:3900} INFO - 0 downstream tasks scheduled from follow-on schedule check
[2024-10-31T19:44:06.735+0000] {local_task_job_runner.py:245} INFO - ::endgroup::
