[2024-10-31T17:13:41.228+0000] {local_task_job_runner.py:123} INFO - ::group::Pre task execution logs
[2024-10-31T17:13:41.257+0000] {taskinstance.py:2612} INFO - Dependencies all met for dep_context=non-requeueable deps ti=<TaskInstance: write_kafka.load_connections scheduled__2024-10-31T16:00:00+00:00 [queued]>
[2024-10-31T17:13:41.275+0000] {taskinstance.py:2612} INFO - Dependencies all met for dep_context=requeueable deps ti=<TaskInstance: write_kafka.load_connections scheduled__2024-10-31T16:00:00+00:00 [queued]>
[2024-10-31T17:13:41.276+0000] {taskinstance.py:2865} INFO - Starting attempt 1 of 2
[2024-10-31T17:13:41.635+0000] {taskinstance.py:2888} INFO - Executing <Task(PythonOperator): load_connections> on 2024-10-31 16:00:00+00:00
[2024-10-31T17:13:41.647+0000] {warnings.py:112} WARNING - /home/***/.local/lib/python3.12/site-packages/***/task/task_runner/standard_task_runner.py:70: DeprecationWarning: This process (pid=2971) is multi-threaded, use of fork() may lead to deadlocks in the child.
  pid = os.fork()

[2024-10-31T17:13:41.649+0000] {standard_task_runner.py:72} INFO - Started process 2980 to run task
[2024-10-31T17:13:41.650+0000] {standard_task_runner.py:104} INFO - Running: ['***', 'tasks', 'run', 'write_kafka', 'load_connections', 'scheduled__2024-10-31T16:00:00+00:00', '--job-id', '5', '--raw', '--subdir', 'DAGS_FOLDER/write_kafka.py', '--cfg-path', '/tmp/tmp0qy88cxq']
[2024-10-31T17:13:41.655+0000] {standard_task_runner.py:105} INFO - Job 5: Subtask load_connections
[2024-10-31T17:13:41.732+0000] {task_command.py:467} INFO - Running <TaskInstance: write_kafka.load_connections scheduled__2024-10-31T16:00:00+00:00 [running]> on host beba2d03a603
[2024-10-31T17:13:41.846+0000] {taskinstance.py:3131} INFO - Exporting env vars: AIRFLOW_CTX_DAG_OWNER='***' AIRFLOW_CTX_DAG_ID='write_kafka' AIRFLOW_CTX_TASK_ID='load_connections' AIRFLOW_CTX_EXECUTION_DATE='2024-10-31T16:00:00+00:00' AIRFLOW_CTX_TRY_NUMBER='1' AIRFLOW_CTX_DAG_RUN_ID='scheduled__2024-10-31T16:00:00+00:00'
[2024-10-31T17:13:41.848+0000] {taskinstance.py:731} INFO - ::endgroup::
[2024-10-31T17:13:41.855+0000] {crypto.py:82} WARNING - empty cryptography key - values will not be stored encrypted.
[2024-10-31T17:13:41.868+0000] {python.py:240} INFO - Done. Returned value was: None
[2024-10-31T17:13:41.884+0000] {taskinstance.py:340} INFO - ::group::Post task execution logs
[2024-10-31T17:13:41.885+0000] {taskinstance.py:352} INFO - Marking task as SUCCESS. dag_id=write_kafka, task_id=load_connections, run_id=scheduled__2024-10-31T16:00:00+00:00, execution_date=20241031T160000, start_date=20241031T171341, end_date=20241031T171341
[2024-10-31T17:13:41.948+0000] {local_task_job_runner.py:266} INFO - Task exited with return code 0
[2024-10-31T17:13:41.998+0000] {taskinstance.py:3900} INFO - 0 downstream tasks scheduled from follow-on schedule check
[2024-10-31T17:13:42.002+0000] {local_task_job_runner.py:245} INFO - ::endgroup::
[2024-10-31T17:40:05.512+0000] {local_task_job_runner.py:123} INFO - ::group::Pre task execution logs
[2024-10-31T17:40:05.536+0000] {taskinstance.py:2612} INFO - Dependencies all met for dep_context=non-requeueable deps ti=<TaskInstance: write_kafka.load_connections scheduled__2024-10-31T16:00:00+00:00 [queued]>
[2024-10-31T17:40:05.549+0000] {taskinstance.py:2612} INFO - Dependencies all met for dep_context=requeueable deps ti=<TaskInstance: write_kafka.load_connections scheduled__2024-10-31T16:00:00+00:00 [queued]>
[2024-10-31T17:40:05.550+0000] {taskinstance.py:2865} INFO - Starting attempt 1 of 2
[2024-10-31T17:40:05.877+0000] {taskinstance.py:2888} INFO - Executing <Task(PythonOperator): load_connections> on 2024-10-31 16:00:00+00:00
[2024-10-31T17:40:05.886+0000] {warnings.py:112} WARNING - /home/***/.local/lib/python3.12/site-packages/***/task/task_runner/standard_task_runner.py:70: DeprecationWarning: This process (pid=85) is multi-threaded, use of fork() may lead to deadlocks in the child.
  pid = os.fork()

[2024-10-31T17:40:05.889+0000] {standard_task_runner.py:72} INFO - Started process 90 to run task
[2024-10-31T17:40:05.888+0000] {standard_task_runner.py:104} INFO - Running: ['***', 'tasks', 'run', 'write_kafka', 'load_connections', 'scheduled__2024-10-31T16:00:00+00:00', '--job-id', '4', '--raw', '--subdir', 'DAGS_FOLDER/write_kafka.py', '--cfg-path', '/tmp/tmp_o1q7bv8']
[2024-10-31T17:40:05.892+0000] {standard_task_runner.py:105} INFO - Job 4: Subtask load_connections
[2024-10-31T17:40:05.971+0000] {task_command.py:467} INFO - Running <TaskInstance: write_kafka.load_connections scheduled__2024-10-31T16:00:00+00:00 [running]> on host 764f828e7588
[2024-10-31T17:40:06.098+0000] {taskinstance.py:3131} INFO - Exporting env vars: AIRFLOW_CTX_DAG_OWNER='***' AIRFLOW_CTX_DAG_ID='write_kafka' AIRFLOW_CTX_TASK_ID='load_connections' AIRFLOW_CTX_EXECUTION_DATE='2024-10-31T16:00:00+00:00' AIRFLOW_CTX_TRY_NUMBER='1' AIRFLOW_CTX_DAG_RUN_ID='scheduled__2024-10-31T16:00:00+00:00'
[2024-10-31T17:40:06.100+0000] {taskinstance.py:731} INFO - ::endgroup::
[2024-10-31T17:40:06.104+0000] {crypto.py:82} WARNING - empty cryptography key - values will not be stored encrypted.
[2024-10-31T17:40:06.129+0000] {taskinstance.py:3310} ERROR - Task failed with exception
Traceback (most recent call last):
  File "/home/airflow/.local/lib/python3.12/site-packages/sqlalchemy/engine/base.py", line 1910, in _execute_context
    self.dialect.do_execute(
  File "/home/airflow/.local/lib/python3.12/site-packages/sqlalchemy/engine/default.py", line 736, in do_execute
    cursor.execute(statement, parameters)
psycopg2.errors.UniqueViolation: duplicate key value violates unique constraint "connection_conn_id_uq"
DETAIL:  Key (conn_id)=(t1-3) already exists.


The above exception was the direct cause of the following exception:

Traceback (most recent call last):
  File "/home/airflow/.local/lib/python3.12/site-packages/airflow/models/taskinstance.py", line 767, in _execute_task
    result = _execute_callable(context=context, **execute_callable_kwargs)
             ^^^^^^^^^^^^^^^^^^^^^^^^^^^^^^^^^^^^^^^^^^^^^^^^^^^^^^^^^^^^^
  File "/home/airflow/.local/lib/python3.12/site-packages/airflow/models/taskinstance.py", line 733, in _execute_callable
    return ExecutionCallableRunner(
           ^^^^^^^^^^^^^^^^^^^^^^^^
  File "/home/airflow/.local/lib/python3.12/site-packages/airflow/utils/operator_helpers.py", line 252, in run
    return self.func(*args, **kwargs)
           ^^^^^^^^^^^^^^^^^^^^^^^^^^
  File "/home/airflow/.local/lib/python3.12/site-packages/airflow/models/baseoperator.py", line 406, in wrapper
    return func(self, *args, **kwargs)
           ^^^^^^^^^^^^^^^^^^^^^^^^^^^
  File "/home/airflow/.local/lib/python3.12/site-packages/airflow/operators/python.py", line 238, in execute
    return_value = self.execute_callable()
                   ^^^^^^^^^^^^^^^^^^^^^^^
  File "/home/airflow/.local/lib/python3.12/site-packages/airflow/operators/python.py", line 256, in execute_callable
    return runner.run(*self.op_args, **self.op_kwargs)
           ^^^^^^^^^^^^^^^^^^^^^^^^^^^^^^^^^^^^^^^^^^^
  File "/home/airflow/.local/lib/python3.12/site-packages/airflow/utils/operator_helpers.py", line 252, in run
    return self.func(*args, **kwargs)
           ^^^^^^^^^^^^^^^^^^^^^^^^^^
  File "/opt/airflow/dags/write_kafka.py", line 28, in load_connections
    db.merge_conn(
  File "/home/airflow/.local/lib/python3.12/site-packages/airflow/utils/session.py", line 97, in wrapper
    return func(*args, session=session, **kwargs)
           ^^^^^^^^^^^^^^^^^^^^^^^^^^^^^^^^^^^^^^
  File "/home/airflow/.local/lib/python3.12/site-packages/airflow/utils/db.py", line 134, in merge_conn
    session.commit()
  File "/home/airflow/.local/lib/python3.12/site-packages/sqlalchemy/orm/session.py", line 1454, in commit
    self._transaction.commit(_to_root=self.future)
  File "/home/airflow/.local/lib/python3.12/site-packages/sqlalchemy/orm/session.py", line 832, in commit
    self._prepare_impl()
  File "/home/airflow/.local/lib/python3.12/site-packages/sqlalchemy/orm/session.py", line 811, in _prepare_impl
    self.session.flush()
  File "/home/airflow/.local/lib/python3.12/site-packages/sqlalchemy/orm/session.py", line 3449, in flush
    self._flush(objects)
  File "/home/airflow/.local/lib/python3.12/site-packages/sqlalchemy/orm/session.py", line 3588, in _flush
    with util.safe_reraise():
         ^^^^^^^^^^^^^^^^^^^
  File "/home/airflow/.local/lib/python3.12/site-packages/sqlalchemy/util/langhelpers.py", line 70, in __exit__
    compat.raise_(
  File "/home/airflow/.local/lib/python3.12/site-packages/sqlalchemy/util/compat.py", line 211, in raise_
    raise exception
  File "/home/airflow/.local/lib/python3.12/site-packages/sqlalchemy/orm/session.py", line 3549, in _flush
    flush_context.execute()
  File "/home/airflow/.local/lib/python3.12/site-packages/sqlalchemy/orm/unitofwork.py", line 456, in execute
    rec.execute(self)
  File "/home/airflow/.local/lib/python3.12/site-packages/sqlalchemy/orm/unitofwork.py", line 630, in execute
    util.preloaded.orm_persistence.save_obj(
  File "/home/airflow/.local/lib/python3.12/site-packages/sqlalchemy/orm/persistence.py", line 245, in save_obj
    _emit_insert_statements(
  File "/home/airflow/.local/lib/python3.12/site-packages/sqlalchemy/orm/persistence.py", line 1238, in _emit_insert_statements
    result = connection._execute_20(
             ^^^^^^^^^^^^^^^^^^^^^^^
  File "/home/airflow/.local/lib/python3.12/site-packages/sqlalchemy/engine/base.py", line 1710, in _execute_20
    return meth(self, args_10style, kwargs_10style, execution_options)
           ^^^^^^^^^^^^^^^^^^^^^^^^^^^^^^^^^^^^^^^^^^^^^^^^^^^^^^^^^^^
  File "/home/airflow/.local/lib/python3.12/site-packages/sqlalchemy/sql/elements.py", line 334, in _execute_on_connection
    return connection._execute_clauseelement(
           ^^^^^^^^^^^^^^^^^^^^^^^^^^^^^^^^^^
  File "/home/airflow/.local/lib/python3.12/site-packages/sqlalchemy/engine/base.py", line 1577, in _execute_clauseelement
    ret = self._execute_context(
          ^^^^^^^^^^^^^^^^^^^^^^
  File "/home/airflow/.local/lib/python3.12/site-packages/sqlalchemy/engine/base.py", line 1953, in _execute_context
    self._handle_dbapi_exception(
  File "/home/airflow/.local/lib/python3.12/site-packages/sqlalchemy/engine/base.py", line 2134, in _handle_dbapi_exception
    util.raise_(
  File "/home/airflow/.local/lib/python3.12/site-packages/sqlalchemy/util/compat.py", line 211, in raise_
    raise exception
  File "/home/airflow/.local/lib/python3.12/site-packages/sqlalchemy/engine/base.py", line 1910, in _execute_context
    self.dialect.do_execute(
  File "/home/airflow/.local/lib/python3.12/site-packages/sqlalchemy/engine/default.py", line 736, in do_execute
    cursor.execute(statement, parameters)
sqlalchemy.exc.IntegrityError: (psycopg2.errors.UniqueViolation) duplicate key value violates unique constraint "connection_conn_id_uq"
DETAIL:  Key (conn_id)=(t1-3) already exists.

[SQL: INSERT INTO connection (conn_id, conn_type, description, host, schema, login, password, port, is_encrypted, is_extra_encrypted, extra) VALUES (%(conn_id)s, %(conn_type)s, %(description)s, %(host)s, %(schema)s, %(login)s, %(password)s, %(port)s, %(is_encrypted)s, %(is_extra_encrypted)s, %(extra)s) RETURNING connection.id]
[parameters: {'conn_id': 't1-3', 'conn_type': 'kafka', 'description': None, 'host': None, 'schema': None, 'login': None, 'password': None, 'port': None, 'is_encrypted': False, 'is_extra_encrypted': False, 'extra': '{"socket.timeout.ms": 10, "bootstrap.servers": "broker:29092"}'}]
(Background on this error at: https://sqlalche.me/e/14/gkpj)
[2024-10-31T17:40:06.180+0000] {taskinstance.py:1225} INFO - Marking task as UP_FOR_RETRY. dag_id=write_kafka, task_id=load_connections, run_id=scheduled__2024-10-31T16:00:00+00:00, execution_date=20241031T160000, start_date=20241031T174005, end_date=20241031T174006
[2024-10-31T17:40:06.219+0000] {taskinstance.py:340} INFO - ::group::Post task execution logs
[2024-10-31T17:40:06.220+0000] {standard_task_runner.py:124} ERROR - Failed to execute job 4 for task load_connections ((psycopg2.errors.UniqueViolation) duplicate key value violates unique constraint "connection_conn_id_uq"
DETAIL:  Key (conn_id)=(t1-3) already exists.

[SQL: INSERT INTO connection (conn_id, conn_type, description, host, schema, login, password, port, is_encrypted, is_extra_encrypted, extra) VALUES (%(conn_id)s, %(conn_type)s, %(description)s, %(host)s, %(schema)s, %(login)s, %(password)s, %(port)s, %(is_encrypted)s, %(is_extra_encrypted)s, %(extra)s) RETURNING connection.id]
[parameters: {'conn_id': 't1-3', 'conn_type': 'kafka', 'description': None, 'host': None, 'schema': None, 'login': None, 'password': None, 'port': None, 'is_encrypted': False, 'is_extra_encrypted': False, 'extra': '{"socket.timeout.ms": 10, "bootstrap.servers": "broker:29092"}'}]
(Background on this error at: https://sqlalche.me/e/14/gkpj); 90)
Traceback (most recent call last):
  File "/home/airflow/.local/lib/python3.12/site-packages/sqlalchemy/engine/base.py", line 1910, in _execute_context
    self.dialect.do_execute(
  File "/home/airflow/.local/lib/python3.12/site-packages/sqlalchemy/engine/default.py", line 736, in do_execute
    cursor.execute(statement, parameters)
psycopg2.errors.UniqueViolation: duplicate key value violates unique constraint "connection_conn_id_uq"
DETAIL:  Key (conn_id)=(t1-3) already exists.


The above exception was the direct cause of the following exception:

Traceback (most recent call last):
  File "/home/airflow/.local/lib/python3.12/site-packages/airflow/task/task_runner/standard_task_runner.py", line 117, in _start_by_fork
    ret = args.func(args, dag=self.dag)
          ^^^^^^^^^^^^^^^^^^^^^^^^^^^^^
  File "/home/airflow/.local/lib/python3.12/site-packages/airflow/cli/cli_config.py", line 49, in command
    return func(*args, **kwargs)
           ^^^^^^^^^^^^^^^^^^^^^
  File "/home/airflow/.local/lib/python3.12/site-packages/airflow/utils/cli.py", line 115, in wrapper
    return f(*args, **kwargs)
           ^^^^^^^^^^^^^^^^^^
  File "/home/airflow/.local/lib/python3.12/site-packages/airflow/cli/commands/task_command.py", line 483, in task_run
    task_return_code = _run_task_by_selected_method(args, _dag, ti)
                       ^^^^^^^^^^^^^^^^^^^^^^^^^^^^^^^^^^^^^^^^^^^^
  File "/home/airflow/.local/lib/python3.12/site-packages/airflow/cli/commands/task_command.py", line 256, in _run_task_by_selected_method
    return _run_raw_task(args, ti)
           ^^^^^^^^^^^^^^^^^^^^^^^
  File "/home/airflow/.local/lib/python3.12/site-packages/airflow/cli/commands/task_command.py", line 341, in _run_raw_task
    return ti._run_raw_task(
           ^^^^^^^^^^^^^^^^^
  File "/home/airflow/.local/lib/python3.12/site-packages/airflow/utils/session.py", line 97, in wrapper
    return func(*args, session=session, **kwargs)
           ^^^^^^^^^^^^^^^^^^^^^^^^^^^^^^^^^^^^^^
  File "/home/airflow/.local/lib/python3.12/site-packages/airflow/models/taskinstance.py", line 3004, in _run_raw_task
    return _run_raw_task(
           ^^^^^^^^^^^^^^
  File "/home/airflow/.local/lib/python3.12/site-packages/airflow/models/taskinstance.py", line 273, in _run_raw_task
    TaskInstance._execute_task_with_callbacks(
  File "/home/airflow/.local/lib/python3.12/site-packages/airflow/models/taskinstance.py", line 3158, in _execute_task_with_callbacks
    result = self._execute_task(context, task_orig)
             ^^^^^^^^^^^^^^^^^^^^^^^^^^^^^^^^^^^^^^
  File "/home/airflow/.local/lib/python3.12/site-packages/airflow/models/taskinstance.py", line 3182, in _execute_task
    return _execute_task(self, context, task_orig)
           ^^^^^^^^^^^^^^^^^^^^^^^^^^^^^^^^^^^^^^^
  File "/home/airflow/.local/lib/python3.12/site-packages/airflow/models/taskinstance.py", line 767, in _execute_task
    result = _execute_callable(context=context, **execute_callable_kwargs)
             ^^^^^^^^^^^^^^^^^^^^^^^^^^^^^^^^^^^^^^^^^^^^^^^^^^^^^^^^^^^^^
  File "/home/airflow/.local/lib/python3.12/site-packages/airflow/models/taskinstance.py", line 733, in _execute_callable
    return ExecutionCallableRunner(
           ^^^^^^^^^^^^^^^^^^^^^^^^
  File "/home/airflow/.local/lib/python3.12/site-packages/airflow/utils/operator_helpers.py", line 252, in run
    return self.func(*args, **kwargs)
           ^^^^^^^^^^^^^^^^^^^^^^^^^^
  File "/home/airflow/.local/lib/python3.12/site-packages/airflow/models/baseoperator.py", line 406, in wrapper
    return func(self, *args, **kwargs)
           ^^^^^^^^^^^^^^^^^^^^^^^^^^^
  File "/home/airflow/.local/lib/python3.12/site-packages/airflow/operators/python.py", line 238, in execute
    return_value = self.execute_callable()
                   ^^^^^^^^^^^^^^^^^^^^^^^
  File "/home/airflow/.local/lib/python3.12/site-packages/airflow/operators/python.py", line 256, in execute_callable
    return runner.run(*self.op_args, **self.op_kwargs)
           ^^^^^^^^^^^^^^^^^^^^^^^^^^^^^^^^^^^^^^^^^^^
  File "/home/airflow/.local/lib/python3.12/site-packages/airflow/utils/operator_helpers.py", line 252, in run
    return self.func(*args, **kwargs)
           ^^^^^^^^^^^^^^^^^^^^^^^^^^
  File "/opt/airflow/dags/write_kafka.py", line 28, in load_connections
    db.merge_conn(
  File "/home/airflow/.local/lib/python3.12/site-packages/airflow/utils/session.py", line 97, in wrapper
    return func(*args, session=session, **kwargs)
           ^^^^^^^^^^^^^^^^^^^^^^^^^^^^^^^^^^^^^^
  File "/home/airflow/.local/lib/python3.12/site-packages/airflow/utils/db.py", line 134, in merge_conn
    session.commit()
  File "/home/airflow/.local/lib/python3.12/site-packages/sqlalchemy/orm/session.py", line 1454, in commit
    self._transaction.commit(_to_root=self.future)
  File "/home/airflow/.local/lib/python3.12/site-packages/sqlalchemy/orm/session.py", line 832, in commit
    self._prepare_impl()
  File "/home/airflow/.local/lib/python3.12/site-packages/sqlalchemy/orm/session.py", line 811, in _prepare_impl
    self.session.flush()
  File "/home/airflow/.local/lib/python3.12/site-packages/sqlalchemy/orm/session.py", line 3449, in flush
    self._flush(objects)
  File "/home/airflow/.local/lib/python3.12/site-packages/sqlalchemy/orm/session.py", line 3588, in _flush
    with util.safe_reraise():
         ^^^^^^^^^^^^^^^^^^^
  File "/home/airflow/.local/lib/python3.12/site-packages/sqlalchemy/util/langhelpers.py", line 70, in __exit__
    compat.raise_(
  File "/home/airflow/.local/lib/python3.12/site-packages/sqlalchemy/util/compat.py", line 211, in raise_
    raise exception
  File "/home/airflow/.local/lib/python3.12/site-packages/sqlalchemy/orm/session.py", line 3549, in _flush
    flush_context.execute()
  File "/home/airflow/.local/lib/python3.12/site-packages/sqlalchemy/orm/unitofwork.py", line 456, in execute
    rec.execute(self)
  File "/home/airflow/.local/lib/python3.12/site-packages/sqlalchemy/orm/unitofwork.py", line 630, in execute
    util.preloaded.orm_persistence.save_obj(
  File "/home/airflow/.local/lib/python3.12/site-packages/sqlalchemy/orm/persistence.py", line 245, in save_obj
    _emit_insert_statements(
  File "/home/airflow/.local/lib/python3.12/site-packages/sqlalchemy/orm/persistence.py", line 1238, in _emit_insert_statements
    result = connection._execute_20(
             ^^^^^^^^^^^^^^^^^^^^^^^
  File "/home/airflow/.local/lib/python3.12/site-packages/sqlalchemy/engine/base.py", line 1710, in _execute_20
    return meth(self, args_10style, kwargs_10style, execution_options)
           ^^^^^^^^^^^^^^^^^^^^^^^^^^^^^^^^^^^^^^^^^^^^^^^^^^^^^^^^^^^
  File "/home/airflow/.local/lib/python3.12/site-packages/sqlalchemy/sql/elements.py", line 334, in _execute_on_connection
    return connection._execute_clauseelement(
           ^^^^^^^^^^^^^^^^^^^^^^^^^^^^^^^^^^
  File "/home/airflow/.local/lib/python3.12/site-packages/sqlalchemy/engine/base.py", line 1577, in _execute_clauseelement
    ret = self._execute_context(
          ^^^^^^^^^^^^^^^^^^^^^^
  File "/home/airflow/.local/lib/python3.12/site-packages/sqlalchemy/engine/base.py", line 1953, in _execute_context
    self._handle_dbapi_exception(
  File "/home/airflow/.local/lib/python3.12/site-packages/sqlalchemy/engine/base.py", line 2134, in _handle_dbapi_exception
    util.raise_(
  File "/home/airflow/.local/lib/python3.12/site-packages/sqlalchemy/util/compat.py", line 211, in raise_
    raise exception
  File "/home/airflow/.local/lib/python3.12/site-packages/sqlalchemy/engine/base.py", line 1910, in _execute_context
    self.dialect.do_execute(
  File "/home/airflow/.local/lib/python3.12/site-packages/sqlalchemy/engine/default.py", line 736, in do_execute
    cursor.execute(statement, parameters)
sqlalchemy.exc.IntegrityError: (psycopg2.errors.UniqueViolation) duplicate key value violates unique constraint "connection_conn_id_uq"
DETAIL:  Key (conn_id)=(t1-3) already exists.

[SQL: INSERT INTO connection (conn_id, conn_type, description, host, schema, login, password, port, is_encrypted, is_extra_encrypted, extra) VALUES (%(conn_id)s, %(conn_type)s, %(description)s, %(host)s, %(schema)s, %(login)s, %(password)s, %(port)s, %(is_encrypted)s, %(is_extra_encrypted)s, %(extra)s) RETURNING connection.id]
[parameters: {'conn_id': 't1-3', 'conn_type': 'kafka', 'description': None, 'host': None, 'schema': None, 'login': None, 'password': None, 'port': None, 'is_encrypted': False, 'is_extra_encrypted': False, 'extra': '{"socket.timeout.ms": 10, "bootstrap.servers": "broker:29092"}'}]
(Background on this error at: https://sqlalche.me/e/14/gkpj)
[2024-10-31T17:40:06.266+0000] {local_task_job_runner.py:266} INFO - Task exited with return code 1
[2024-10-31T17:40:06.312+0000] {taskinstance.py:3900} INFO - 0 downstream tasks scheduled from follow-on schedule check
[2024-10-31T17:40:06.323+0000] {local_task_job_runner.py:245} INFO - ::endgroup::
